2022-09-20 00:13:04,992 ERROR: Exception on /auth/login [POST] [in E:\Edu\py\microblog\venv\lib\site-packages\flask\app.py:1741]
Traceback (most recent call last):
  File "E:\Edu\py\microblog\venv\lib\site-packages\sqlalchemy\engine\base.py", line 1900, in _execute_context
    self.dialect.do_execute(
  File "E:\Edu\py\microblog\venv\lib\site-packages\sqlalchemy\engine\default.py", line 736, in do_execute
    cursor.execute(statement, parameters)
sqlite3.OperationalError: no such table: user

The above exception was the direct cause of the following exception:

Traceback (most recent call last):
  File "E:\Edu\py\microblog\venv\lib\site-packages\flask\app.py", line 2525, in wsgi_app
    response = self.full_dispatch_request()
  File "E:\Edu\py\microblog\venv\lib\site-packages\flask\app.py", line 1822, in full_dispatch_request
    rv = self.handle_user_exception(e)
  File "E:\Edu\py\microblog\venv\lib\site-packages\flask\app.py", line 1820, in full_dispatch_request
    rv = self.dispatch_request()
  File "E:\Edu\py\microblog\venv\lib\site-packages\flask\app.py", line 1796, in dispatch_request
    return self.ensure_sync(self.view_functions[rule.endpoint])(**view_args)
  File "E:\Edu\py\microblog\app\auth\routes.py", line 19, in login
    user = User.query.filter_by(username=form.username.data).first()
  File "E:\Edu\py\microblog\venv\lib\site-packages\sqlalchemy\orm\query.py", line 2823, in first
    return self.limit(1)._iter().first()
  File "E:\Edu\py\microblog\venv\lib\site-packages\sqlalchemy\orm\query.py", line 2907, in _iter
    result = self.session.execute(
  File "E:\Edu\py\microblog\venv\lib\site-packages\sqlalchemy\orm\session.py", line 1712, in execute
    result = conn._execute_20(statement, params or {}, execution_options)
  File "E:\Edu\py\microblog\venv\lib\site-packages\sqlalchemy\engine\base.py", line 1705, in _execute_20
    return meth(self, args_10style, kwargs_10style, execution_options)
  File "E:\Edu\py\microblog\venv\lib\site-packages\sqlalchemy\sql\elements.py", line 333, in _execute_on_connection
    return connection._execute_clauseelement(
  File "E:\Edu\py\microblog\venv\lib\site-packages\sqlalchemy\engine\base.py", line 1572, in _execute_clauseelement
    ret = self._execute_context(
  File "E:\Edu\py\microblog\venv\lib\site-packages\sqlalchemy\engine\base.py", line 1943, in _execute_context
    self._handle_dbapi_exception(
  File "E:\Edu\py\microblog\venv\lib\site-packages\sqlalchemy\engine\base.py", line 2124, in _handle_dbapi_exception
    util.raise_(
  File "E:\Edu\py\microblog\venv\lib\site-packages\sqlalchemy\util\compat.py", line 208, in raise_
    raise exception
  File "E:\Edu\py\microblog\venv\lib\site-packages\sqlalchemy\engine\base.py", line 1900, in _execute_context
    self.dialect.do_execute(
  File "E:\Edu\py\microblog\venv\lib\site-packages\sqlalchemy\engine\default.py", line 736, in do_execute
    cursor.execute(statement, parameters)
sqlalchemy.exc.OperationalError: (sqlite3.OperationalError) no such table: user
[SQL: SELECT user.id AS user_id, user.username AS user_username, user.email AS user_email, user.password_hash AS user_password_hash, user.about_me AS user_about_me, user.last_seen AS user_last_seen, user.token AS user_token, user.token_expiration AS user_token_expiration, user.last_message_read_time AS user_last_message_read_time 
FROM user 
WHERE user.username = ?
 LIMIT ? OFFSET ?]
[parameters: ('snx', 1, 0)]
(Background on this error at: https://sqlalche.me/e/14/e3q8)
2022-09-20 00:13:31,927 ERROR: Exception on /auth/login [POST] [in E:\Edu\py\microblog\venv\lib\site-packages\flask\app.py:1741]
Traceback (most recent call last):
  File "E:\Edu\py\microblog\venv\lib\site-packages\sqlalchemy\engine\base.py", line 1900, in _execute_context
    self.dialect.do_execute(
  File "E:\Edu\py\microblog\venv\lib\site-packages\sqlalchemy\engine\default.py", line 736, in do_execute
    cursor.execute(statement, parameters)
sqlite3.OperationalError: no such table: user

The above exception was the direct cause of the following exception:

Traceback (most recent call last):
  File "E:\Edu\py\microblog\venv\lib\site-packages\flask\app.py", line 2525, in wsgi_app
    response = self.full_dispatch_request()
  File "E:\Edu\py\microblog\venv\lib\site-packages\flask\app.py", line 1822, in full_dispatch_request
    rv = self.handle_user_exception(e)
  File "E:\Edu\py\microblog\venv\lib\site-packages\flask\app.py", line 1820, in full_dispatch_request
    rv = self.dispatch_request()
  File "E:\Edu\py\microblog\venv\lib\site-packages\flask\app.py", line 1796, in dispatch_request
    return self.ensure_sync(self.view_functions[rule.endpoint])(**view_args)
  File "E:\Edu\py\microblog\app\auth\routes.py", line 19, in login
    user = User.query.filter_by(username=form.username.data).first()
  File "E:\Edu\py\microblog\venv\lib\site-packages\sqlalchemy\orm\query.py", line 2823, in first
    return self.limit(1)._iter().first()
  File "E:\Edu\py\microblog\venv\lib\site-packages\sqlalchemy\orm\query.py", line 2907, in _iter
    result = self.session.execute(
  File "E:\Edu\py\microblog\venv\lib\site-packages\sqlalchemy\orm\session.py", line 1712, in execute
    result = conn._execute_20(statement, params or {}, execution_options)
  File "E:\Edu\py\microblog\venv\lib\site-packages\sqlalchemy\engine\base.py", line 1705, in _execute_20
    return meth(self, args_10style, kwargs_10style, execution_options)
  File "E:\Edu\py\microblog\venv\lib\site-packages\sqlalchemy\sql\elements.py", line 333, in _execute_on_connection
    return connection._execute_clauseelement(
  File "E:\Edu\py\microblog\venv\lib\site-packages\sqlalchemy\engine\base.py", line 1572, in _execute_clauseelement
    ret = self._execute_context(
  File "E:\Edu\py\microblog\venv\lib\site-packages\sqlalchemy\engine\base.py", line 1943, in _execute_context
    self._handle_dbapi_exception(
  File "E:\Edu\py\microblog\venv\lib\site-packages\sqlalchemy\engine\base.py", line 2124, in _handle_dbapi_exception
    util.raise_(
  File "E:\Edu\py\microblog\venv\lib\site-packages\sqlalchemy\util\compat.py", line 208, in raise_
    raise exception
  File "E:\Edu\py\microblog\venv\lib\site-packages\sqlalchemy\engine\base.py", line 1900, in _execute_context
    self.dialect.do_execute(
  File "E:\Edu\py\microblog\venv\lib\site-packages\sqlalchemy\engine\default.py", line 736, in do_execute
    cursor.execute(statement, parameters)
sqlalchemy.exc.OperationalError: (sqlite3.OperationalError) no such table: user
[SQL: SELECT user.id AS user_id, user.username AS user_username, user.email AS user_email, user.password_hash AS user_password_hash, user.about_me AS user_about_me, user.last_seen AS user_last_seen, user.token AS user_token, user.token_expiration AS user_token_expiration, user.last_message_read_time AS user_last_message_read_time 
FROM user 
WHERE user.username = ?
 LIMIT ? OFFSET ?]
[parameters: ('rug88', 1, 0)]
(Background on this error at: https://sqlalche.me/e/14/e3q8)
2022-09-20 00:16:01,528 INFO: Microblog startup [in E:\Edu\py\microblog\app\__init__.py:89]
2022-09-20 00:16:19,036 INFO: Microblog startup [in E:\Edu\py\microblog\app\__init__.py:89]
2022-09-20 00:18:19,966 INFO: Microblog startup [in E:\Edu\py\microblog\app\__init__.py:89]
2022-09-20 00:19:27,165 INFO: Microblog startup [in E:\Edu\py\microblog\app\__init__.py:89]
